<?xml version="1.0" encoding="utf-8"?>
<!-- This URDF was automatically created by SolidWorks to URDF Exporter! Originally created by Stephen Brawner (brawner@gmail.com) 
     Commit Version: 1.6.0-4-g7f85cfe  Build Version: 1.6.7995.38578
     For more information, please see http://wiki.ros.org/sw_urdf_exporter -->
<robot
  name="xerobotvisai2">
  <link
    name="base_link">
    <inertial>
      <origin
        xyz="-0.00884003371869591 -1.69144292938572E-06 0.023380316286157"
        rpy="0 0 0" />
      <mass
        value="0.139616230876785" />
      <inertia
        ixx="7.5183979078754E-05"
        ixy="-2.38192654544776E-10"
        ixz="-4.01410400424682E-09"
        iyy="8.90639372566359E-05"
        iyz="1.37636143194086E-09"
        izz="0.000152236942898235" />
    </inertial>
    <visual>
      <origin
        xyz="0 0 0"
        rpy="0 0 0" />
      <geometry>
        <mesh
          filename="package://xerobotvisai2/meshes/base_link.STL" />
      </geometry>
      <material
        name="">
        <color
          rgba="0 1 1 1" />
      </material>
    </visual>
    <collision>
      <origin
        xyz="0 0 0"
        rpy="0 0 0" />
      <geometry>
        <mesh
          filename="package://xerobotvisai2/meshes/base_link.STL" />
      </geometry>
    </collision>
  </link>
  <link
    name="trai_link">
    <inertial>
      <origin
        xyz="4.32986979603811E-15 4.71844785465692E-16 -0.00925124739800048"
        rpy="0 0 0" />
      <mass
        value="0.0508844489509995" />
      <inertia
        ixx="2.01105522645016E-05"
        ixy="6.35274710440725E-22"
        ixz="-5.50571415715295E-21"
        iyy="2.01105522645016E-05"
        iyz="6.88214269644119E-21"
        izz="3.52318436020648E-05" />
    </inertial>
    <visual>
      <origin
        xyz="0 0 0"
        rpy="0 0 0" />
      <geometry>
        <mesh
          filename="package://xerobotvisai2/meshes/trai_link.STL" />
      </geometry>
      <material
        name="">
        <color
          rgba="0.792156862745098 0.819607843137255 0.933333333333333 1" />
      </material>
    </visual>
    <collision>
      <origin
        xyz="0 0 0"
        rpy="0 0 0" />
      <geometry>
        <mesh
          filename="package://xerobotvisai2/meshes/trai_link.STL" />
      </geometry>
    </collision>
  </link>
  <joint
    name="trai_joint"
    type="continuous">
    <origin
      xyz="-0.03704 0.087854 0.0215"
      rpy="1.5708 1.0391 -3.1416" />
    <parent
      link="base_link" />
    <child
      link="trai_link" />
    <axis
      xyz="0 0 1" />
  </joint>
  <link
    name="phai_link">
    <inertial>
      <origin
        xyz="5.55111512312578E-17 -5.55111512312578E-17 0.00925124739800157"
        rpy="0 0 0" />
      <mass
        value="0.0508844489509995" />
      <inertia
        ixx="2.01105522645016E-05"
        ixy="-4.2351647362715E-21"
        ixz="-1.18584612615602E-20"
        iyy="2.01105522645016E-05"
        iyz="-4.36221967835965E-20"
        izz="3.52318436020648E-05" />
    </inertial>
    <visual>
      <origin
        xyz="0 0 0"
        rpy="0 0 0" />
      <geometry>
        <mesh
          filename="package://xerobotvisai2/meshes/phai_link.STL" />
      </geometry>
      <material
        name="">
        <color
          rgba="0.792156862745098 0.819607843137255 0.933333333333333 1" />
      </material>
    </visual>
    <collision>
      <origin
        xyz="0 0 0"
        rpy="0 0 0" />
      <geometry>
        <mesh
          filename="package://xerobotvisai2/meshes/phai_link.STL" />
      </geometry>
    </collision>
  </link>
  <joint
    name="phai_joint"
    type="continuous">
    <origin
      xyz="-0.03704 -0.086305 0.0215"
      rpy="-1.5708 -0.58656 0" />
    <parent
      link="base_link" />
    <child
      link="phai_link" />
    <axis
      xyz="0 0 1" />
  </joint>
  <link
    name="taymay1_link">
    <inertial>
      <origin
        xyz="-0.066306404998369 -0.0126376681469407 0.00150000000000056"
        rpy="0 0 0" />
      <mass
        value="0.00846438055098076" />
      <inertia
        ixx="7.91868476694563E-07"
        ixy="-2.58979705717387E-06"
        ixz="1.13952401185305E-19"
        iyy="1.38862264082511E-05"
        iyz="2.43786670131628E-20"
        izz="1.46653983141192E-05" />
    </inertial>
    <visual>
      <origin
        xyz="0 0 0"
        rpy="0 0 0" />
      <geometry>
        <mesh
          filename="package://xerobotvisai2/meshes/taymay1_link.STL" />
      </geometry>
      <material
        name="">
        <color
          rgba="0 1 1 1" />
      </material>
    </visual>
    <collision>
      <origin
        xyz="0 0 0"
        rpy="0 0 0" />
      <geometry>
        <mesh
          filename="package://xerobotvisai2/meshes/taymay1_link.STL" />
      </geometry>
    </collision>
  </link>
  <joint
    name="taymay1_joint"
    type="revolute">
    <origin
      xyz="-0.015427 0 0.067"
      rpy="1.5708 1.0391 3.1416" />
    <parent
      link="base_link" />
    <child
      link="taymay1_link" />
    <axis
      xyz="0 0 1" />
    <limit
      lower="-0.5"
      upper="0.5"
      effort="1"
      velocity="1" />
  </joint>
  <link
    name="taymay2_link">
    <inertial>
      <origin
        xyz="0.0148629315605282 0.0512928982262378 -0.00299999999999973"
        rpy="0 0 0" />
      <mass
        value="0.00655937220510258" />
      <inertia
        ixx="6.27286996240315E-06"
        ixy="-1.75023017922502E-06"
        ixz="-1.67289007082724E-20"
        iyy="7.39874090506564E-07"
        iyz="-5.11396141904784E-20"
        izz="7.00276498347422E-06" />
    </inertial>
    <visual>
      <origin
        xyz="0 0 0"
        rpy="0 0 0" />
      <geometry>
        <mesh
          filename="package://xerobotvisai2/meshes/taymay2_link.STL" />
      </geometry>
      <material
        name="">
        <color
          rgba="0 1 1 1" />
      </material>
    </visual>
    <collision>
      <origin
        xyz="0 0 0"
        rpy="0 0 0" />
      <geometry>
        <mesh
          filename="package://xerobotvisai2/meshes/taymay2_link.STL" />
      </geometry>
    </collision>
  </link>
  <joint
    name="taymay2_joint"
    type="revolute">
    <origin
      xyz="-0.13261 -0.025275 0.003"
      rpy="0 0 -2.689" />
    <parent
      link="taymay1_link" />
    <child
      link="taymay2_link" />
    <axis
      xyz="0 0 1" />
    <limit
      lower="-1.57"
      upper="1.57"
      effort="1"
      velocity="1" />
    <dynamics
      damping="0.01"
      friction="0.01" />
  </joint>
  <link
    name="cam_link">
    <inertial>
      <origin
        xyz="0.0010760427325527 0 1.74369141375808E-06"
        rpy="0 0 0" />
      <mass
        value="0.000112892606467818" />
      <inertia
        ixx="9.02305513481435E-10"
        ixy="6.0746076234363E-25"
        ixz="6.16053270333464E-13"
        iyy="5.22135238423374E-10"
        iyz="2.71418638493962E-25"
        izz="5.22136236717182E-10" />
    </inertial>
    <visual>
      <origin
        xyz="0 0 0"
        rpy="0 0 0" />
      <geometry>
        <mesh
          filename="package://xerobotvisai2/meshes/cam_link.STL" />
      </geometry>
      <material
        name="">
        <color
          rgba="1 1 0 1" />
      </material>
    </visual>
    <collision>
      <origin
        xyz="0 0 0"
        rpy="0 0 0" />
      <geometry>
        <mesh
          filename="package://xerobotvisai2/meshes/cam_link.STL" />
      </geometry>
    </collision>
  </link>
  <joint
    name="cam_joint"
    type="fixed">
    <origin
      xyz="0.08096 0 0.042"
      rpy="0.00080435 0.0016205 0" />
    <parent
      link="base_link" />
    <child
      link="cam_link" />
    <axis
      xyz="0 0 0" />
    <limit
      lower="0"
      upper="0"
      effort="0"
      velocity="0" />
  </joint>
  <link
    name="lidar_link">
    <inertial>
      <origin
        xyz="0.0030796201092603 -5.55111512312578E-17 0.00625772986909287"
        rpy="0 0 0" />
      <mass
        value="0.0190134653448062" />
      <inertia
        ixx="1.94902167564129E-06"
        ixy="3.21872519956634E-20"
        ixz="2.1691505996885E-07"
        iyy="3.17269167170879E-06"
        iyz="-5.0821976835258E-21"
        izz="4.11310538100717E-06" />
    </inertial>
    <visual>
      <origin
        xyz="0 0 0"
        rpy="0 0 0" />
      <geometry>
        <mesh
          filename="package://xerobotvisai2/meshes/lidar_link.STL" />
      </geometry>
      <material
        name="">
        <color
          rgba="0 1 0.250980392156863 1" />
      </material>
    </visual>
    <collision>
      <origin
        xyz="0 0 0"
        rpy="0 0 0" />
      <geometry>
        <mesh
          filename="package://xerobotvisai2/meshes/lidar_link.STL" />
      </geometry>
    </collision>
  </link>
  <joint
    name="lidar_joint"
    type="fixed">
    <origin
      xyz="0.046316 0 0.048"
      rpy="0 0 0" />
    <parent
      link="base_link" />
    <child
      link="lidar_link" />
    <axis
      xyz="0 0 0" />
  </joint>
  <link
    name="gps_link">
    <inertial>
      <origin
        xyz="0 -5.55111512312578E-17 0.00125777206333164"
        rpy="0 0 0" />
      <mass
        value="0.000523999999999999" />
      <inertia
        ixx="1.42057330840943E-08"
        ixy="-1.63574966132361E-22"
        ixz="2.06795153138257E-24"
        iyy="7.3667330840943E-09"
        iyz="2.06795153138257E-25"
        izz="2.04783333333332E-08" />
    </inertial>
    <visual>
      <origin
        xyz="0 0 0"
        rpy="0 0 0" />
      <geometry>
        <mesh
          filename="package://xerobotvisai2/meshes/gps_link.STL" />
      </geometry>
      <material
        name="">
        <color
          rgba="0.792156862745098 0.819607843137255 0.933333333333333 1" />
      </material>
    </visual>
    <collision>
      <origin
        xyz="0 0 0"
        rpy="0 0 0" />
      <geometry>
        <mesh
          filename="package://xerobotvisai2/meshes/gps_link.STL" />
      </geometry>
    </collision>
  </link>
  <joint
    name="gps_joint"
    type="fixed">
    <origin
      xyz="-0.048243 0 0.043"
      rpy="0 0 0" />
    <parent
      link="base_link" />
    <child
      link="gps_link" />
    <axis
      xyz="0 0 0" />
  </joint>
  <gazebo>
    <plugin name="differential_drive_controller" filename="libgazebo_ros_diff_drive.so">
      <updateRate>50</updateRate>
      <leftJoint>trai_joint</leftJoint>
      <rightJoint>phai_joint</rightJoint>
      <wheelSeparation>0.5380</wheelSeparation>
      <wheelDiameter>0.2410</wheelDiameter>
      <wheelAcceleration>1.0</wheelAcceleration>
      <wheelTorque>20</wheelTorque>
      <commandTopic>cmd_vel</commandTopic>
      <odometryTopic>odom</odometryTopic>
      <odometryFrame>odom</odometryFrame>
      <robotBaseFrame>base_link</robotBaseFrame>
      <odometrySource>1</odometrySource>
      <publishWheelTF>true</publishWheelTF>
      <publishOdom>true</publishOdom>
      <publishWheelJointState>true</publishWheelJointState>
      <legacyMode>false</legacyMode>
    </plugin>
  </gazebo>

  <gazebo reference="base_link">
    <material>Gazebo/Turquoise</material>
  </gazebo>
  <gazebo reference="trai_link">
    <material>Gazebo/Black</material>
    </gazebo>
  <gazebo reference="phai_link">
    <material>Gazebo/Black</material>
    </gazebo>
  <gazebo reference="taymay1_link">
    <material>Gazebo/Blue</material>
    </gazebo>
  <gazebo reference="taymay2_link">
    <material>Gazebo/Blue</material>
    </gazebo>
  <gazebo reference="cam_link">
    <material>Gazebo/Yellow</material>
    </gazebo>
  <gazebo reference="gps_link">
    <material>Gazebo/Green</material>
    </gazebo>
  <gazebo reference="lidar_link">
    <material>Gazebo/Red</material>
  </gazebo>

  <gazebo reference="cam_link">
    <sensor type="camera" name="camera1">
      <update_rate>30.0</update_rate>
      <camera name="head">
        <horizontal_fov>1.3962634</horizontal_fov>
        <image>
          <width>800</width>
          <height>800</height>
          <format>R8G8B8</format>
        </image>
        <clip>
          <near>0.02</near>
          <far>300</far>
        </clip>
        <noise>
          <type>gaussian</type>
          <mean>0.0</mean>
          <stddev>0.007</stddev>
        </noise>
      </camera>
      <plugin name="camera_controller" filename="libgazebo_ros_camera.so">
        <alwaysOn>true</alwaysOn>
        <updateRate>0.0</updateRate>
        <cameraName>rrbot/camera1</cameraName>
        <imageTopicName>image_raw</imageTopicName>
        <cameraInfoTopicName>camera_info</cameraInfoTopicName>
        <frameName>camera_link</frameName>
        <hackBaseline>0.07</hackBaseline>
        <distortionK1>0.0</distortionK1>
        <distortionK2>0.0</distortionK2>
        <distortionK3>0.0</distortionK3>
        <distortionT1>0.0</distortionT1>
        <distortionT2>0.0</distortionT2>
      </plugin>
    </sensor>
  </gazebo>

  <gazebo reference="lidar_link">
      <sensor type="ray" name="lidar_sensor">
        <pose>0 0 0 0 0 0</pose>
        <visualize>true</visualize>
        <update_rate>30</update_rate>
        <ray>
          <scan>
            <horizontal>
              <samples>720</samples>
              <resolution>1</resolution>
              <min_angle>-1.5708</min_angle>
              <max_angle>1.5708</max_angle>
            </horizontal>
          </scan>
          <range>
            <min>0.1</min>
            <max>30.0</max>
            <resolution>0.01</resolution>
          </range>
          <noise>
            <type>gaussian</type>
            <mean>0.0</mean>
            <stddev>0.01</stddev>
          </noise>
        </ray>
        <plugin name="gazebo_ros_laser" filename="libgazebo_ros_laser.so">
          <topicName>/scan</topicName>
          <frameName>lidar_link</frameName>
        </plugin>
      </sensor>
  </gazebo>

  <gazebo>
    <plugin name="gazebo_ros_gps" filename="libhector_gazebo_ros_gps.so">
      <updateRate>4.0</updateRate>
      <bodyName>gps_link</bodyName>
      <frameId>gps_link</frameId>
      <topicName>/gps/fix</topicName>
      <velocityTopicName>/gps/fix_velocity</velocityTopicName>
      <referenceLatitude>-30.06022459407145675</referenceLatitude>
      <referenceLongitude>-51.173913575780311191</referenceLongitude>
      <referenceHeading>90</referenceHeading>
      <referenceAltitude>10</referenceAltitude>
      <offset>0 0 0</offset>
      <drift>0.001 0.001 0.001</drift>
      <gaussianNoise>0.05 0.05 0.05</gaussianNoise>
      <velocityDrift>0.001 0.001 0.001</velocityDrift>
      <velocityGaussianNoise>0.5 0.5 0.5</velocityGaussianNoise>
    </plugin>
  </gazebo>

<transmission name="taymay1_joint_transmission">
    <type>transmission_interface/SimpleTransmission</type>
    <joint name="taymay1_joint">
      <hardwareInterface>hardware_interface/PositionJointInterface</hardwareInterface>
    </joint>
    <actuator name="link1_servo">
      <mechanicalReduction>1.0</mechanicalReduction>
    </actuator>
</transmission>

<transmission name="taymay2_joint_transmission">
    <type>transmission_interface/SimpleTransmission</type>
    <joint name="taymay2_joint">
      <hardwareInterface>hardware_interface/PositionJointInterface</hardwareInterface>
    </joint>
    <actuator name="link2_servo">
      <mechanicalReduction>1.0</mechanicalReduction>
    </actuator>
</transmission>
  

  <gazebo>
    <plugin name="gazebo_ros_control" filename="libgazebo_ros_control.so">
      <robotNamespace>/</robotNamespace>
      <robotSimType>gazebo_ros_control/DefaultRobotHWSim</robotSimType>
      <legacyModeNS>false</legacyModeNS>
      <controlPeriod>0.001</controlPeriod>
    </plugin>
  </gazebo>
</robot>